Workbook

Sheet Cases
A1: id | B1: formula | C1: type | D1: error_type | E1: length
A2: K-0001 | B2: =1+1 -> 2 | C2: =TYPE(B2) -> 1 | D2: =IFERROR(_xlfn.ERROR.TYPE(B2),"") | E2: =LEN(B2&"") -> 1
A3: K-0002 | B3: =0.1+0.2 -> 0.3 | C3: =TYPE(B3) -> 1 | D3: =IFERROR(_xlfn.ERROR.TYPE(B3),"") | E3: =LEN(B3&"") -> 3
A4: P-0001 | B4: =-2^2 -> 4 | C4: =TYPE(B4) -> 1 | D4: =IFERROR(_xlfn.ERROR.TYPE(B4),"") | E4: =LEN(B4&"") -> 1
A5: P-0002 | B5: =0-2^2 -> -4 | C5: =TYPE(B5) -> 1 | D5: =IFERROR(_xlfn.ERROR.TYPE(B5),"") | E5: =LEN(B5&"") -> 2
A6: P-0003 | B6: =2^3^2 -> 512 | C6: =TYPE(B6) -> 1 | D6: =IFERROR(_xlfn.ERROR.TYPE(B6),"") | E6: =LEN(B6&"") -> 3
A7: P-0004 | B7: =-2^0.5 -> #NUM! | C7: =TYPE(B7) -> 16 | D7: =IFERROR(_xlfn.ERROR.TYPE(B7),"") -> 6 | E7: =LEN(B7&"") -> #NUM!
A8: P-0005 | B8: =50% -> 0.5 | C8: =TYPE(B8) -> 1 | D8: =IFERROR(_xlfn.ERROR.TYPE(B8),"") | E8: =LEN(B8&"") -> 3
A9: P-0006 | B9: =2*50% -> 1 | C9: =TYPE(B9) -> 1 | D9: =IFERROR(_xlfn.ERROR.TYPE(B9),"") | E9: =LEN(B9&"") -> 1
A10: P-0007 | B10: =2^50% -> 1.4142136 | C10: =TYPE(B10) -> 1 | D10: =IFERROR(_xlfn.ERROR.TYPE(B10),"") | E10: =LEN(B10&"") -> 15
A11: P-0008 | B11: =-50% -> -0.5 | C11: =TYPE(B11) -> 1 | D11: =IFERROR(_xlfn.ERROR.TYPE(B11),"") | E11: =LEN(B11&"") -> 4
A12: P-0009 | B12: =10%% -> #ERROR! | C12: =TYPE(B12) -> 16 | D12: =IFERROR(_xlfn.ERROR.TYPE(B12),"") -> 8 | E12: =LEN(B12&"") -> #ERROR!
A13: P-0010 | B13: =1+2*3 -> 7 | C13: =TYPE(B13) -> 1 | D13: =IFERROR(_xlfn.ERROR.TYPE(B13),"") | E13: =LEN(B13&"") -> 1
A14: P-0011 | B14: =(1+2)*3 -> 9 | C14: =TYPE(B14) -> 1 | D14: =IFERROR(_xlfn.ERROR.TYPE(B14),"") | E14: =LEN(B14&"") -> 1
A15: P-0012 | B15: ="a"&1+2 -> a3 | C15: =TYPE(B15) -> 2 | D15: =IFERROR(_xlfn.ERROR.TYPE(B15),"") | E15: =LEN(B15&"") -> 2
A16: P-0013 | B16: =1&2=12 -> FALSE | C16: =TYPE(B16) -> 4 | D16: =IFERROR(_xlfn.ERROR.TYPE(B16),"") | E16: =LEN(B16&"") -> 5
A17: P-0014 | B17: =1=1=TRUE -> TRUE | C17: =TYPE(B17) -> 4 | D17: =IFERROR(_xlfn.ERROR.TYPE(B17),"") | E17: =LEN(B17&"") -> 4
A18: P-0015 | B18: =--"3" -> 3 | C18: =TYPE(B18) -> 1 | D18: =IFERROR(_xlfn.ERROR.TYPE(B18),"") | E18: =LEN(B18&"") -> 1
A19: P-0016 | B19: =+"3" -> 3 | C19: =TYPE(B19) -> 2 | D19: =IFERROR(_xlfn.ERROR.TYPE(B19),"") | E19: =LEN(B19&"") -> 1
A20: P-0017 | B20: ="say ""hi""" -> say "hi" | C20: =TYPE(B20) -> 2 | D20: =IFERROR(_xlfn.ERROR.TYPE(B20),"") | E20: =LEN(B20&"") -> 8
A21: P-0018 | B21: =0.5+100 -> 100.5 | C21: =TYPE(B21) -> 1 | D21: =IFERROR(_xlfn.ERROR.TYPE(B21),"") | E21: =LEN(B21&"") -> 5
A22: P-0019 | B22: =0.001*1000 -> 1 | C22: =TYPE(B22) -> 1 | D22: =IFERROR(_xlfn.ERROR.TYPE(B22),"") | E22: =LEN(B22&"") -> 1
A23: P-0020 | B23: {=SUM({1,2;3,4})} -> 10 | C23: =TYPE(B23) -> 1 | D23: =IFERROR(_xlfn.ERROR.TYPE(B23),"") | E23: =LEN(B23&"") -> 2
A24: P-0021 | B24: {=ROWS({1,2;3,4})} -> 2 | C24: =TYPE(B24) -> 1 | D24: =IFERROR(_xlfn.ERROR.TYPE(B24),"") | E24: =LEN(B24&"") -> 1
A25: P-0022 | B25: {=COLUMNS({1,2,3})} -> 3 | C25: =TYPE(B25) -> 1 | D25: =IFERROR(_xlfn.ERROR.TYPE(B25),"") | E25: =LEN(B25&"") -> 1
A26: P-0023 | B26: {=SUM({1,2}*{3,4})} -> 3 | C26: =TYPE(B26) -> 1 | D26: =IFERROR(_xlfn.ERROR.TYPE(B26),"") | E26: =LEN(B26&"") -> 1
A27: P-0024 | B27: =sum(1,2) -> 3 | C27: =TYPE(B27) -> 1 | D27: =IFERROR(_xlfn.ERROR.TYPE(B27),"") | E27: =LEN(B27&"") -> 1
A28: P-0025 | B28: =SUM(Inputs!B1:B5) -> 15 | C28: =TYPE(B28) -> 1 | D28: =IFERROR(_xlfn.ERROR.TYPE(B28),"") | E28: =LEN(B28&"") -> 2
A29: P-0026 | B29: =SUM(Inputs!$B$1:$B$5) -> 15 | C29: =TYPE(B29) -> 1 | D29: =IFERROR(_xlfn.ERROR.TYPE(B29),"") | E29: =LEN(B29&"") -> 2
A30: P-0027 | B30: =SUM(Inputs!B:B) -> 15 | C30: =TYPE(B30) -> 1 | D30: =IFERROR(_xlfn.ERROR.TYPE(B30),"") | E30: =LEN(B30&"") -> 2
A31: P-0028 | B31: {=INDEX({10,20;30,40},2,1)} -> 30 | C31: =TYPE(B31) -> 1 | D31: =IFERROR(_xlfn.ERROR.TYPE(B31),"") | E31: =LEN(B31&"") -> 2
A32: P-0029 | B32: {=SUM({Inputs!B1,Inputs!B2})} -> 3 | C32: =TYPE(B32) -> 1 | D32: =IFERROR(_xlfn.ERROR.TYPE(B32),"") | E32: =LEN(B32&"") -> 1
A33: P-0030 | B33: =_xlfn.ERROR.TYPE(#NULL!) -> 1 | C33: =TYPE(B33) -> 1 | D33: =IFERROR(_xlfn.ERROR.TYPE(B33),"") | E33: =LEN(B33&"") -> 1
A34: P-0031 | B34: =_xlfn.ERROR.TYPE(#ERROR!) -> 8 | C34: =TYPE(B34) -> 1 | D34: =IFERROR(_xlfn.ERROR.TYPE(B34),"") | E34: =LEN(B34&"") -> 1
A35: P-0032 | B35: =_xlfn.ERROR.TYPE(#N/A) -> 7 | C35: =TYPE(B35) -> 1 | D35: =IFERROR(_xlfn.ERROR.TYPE(B35),"") | E35: =LEN(B35&"") -> 1
A36: P-0033 | B36: =1/0 -> #DIV/0! | C36: =TYPE(B36) -> 16 | D36: =IFERROR(_xlfn.ERROR.TYPE(B36),"") -> 2 | E36: =LEN(B36&"") -> #DIV/0!
A37: P-0034 | B37: =TRUE+TRUE -> 2 | C37: =TYPE(B37) -> 1 | D37: =IFERROR(_xlfn.ERROR.TYPE(B37),"") | E37: =LEN(B37&"") -> 1
A38: P-0035 | B38: =2^-1 -> 0.5 | C38: =TYPE(B38) -> 1 | D38: =IFERROR(_xlfn.ERROR.TYPE(B38),"") | E38: =LEN(B38&"") -> 3
A39: P-0036 | B39: =-(-3) -> 3 | C39: =TYPE(B39) -> 1 | D39: =IFERROR(_xlfn.ERROR.TYPE(B39),"") | E39: =LEN(B39&"") -> 1
A40: P-0037 | B40: =3-(-2) -> 5 | C40: =TYPE(B40) -> 1 | D40: =IFERROR(_xlfn.ERROR.TYPE(B40),"") | E40: =LEN(B40&"") -> 1
...

Sheet Inputs
A1: 10 | B1: 1 | C1: min_qty | D1: unit_price | E1: 30 | F1: c | G1: apple | H1: 100 | I1: 46307 | J1: =1+1 | K1: a | L1: b | M1: c | N1: d | P1: >=200 | Q1: 0.3 | R1: found | S1: 0 | T1: 0 | U1: 0 | V1: 0.03 | W1: 0 | X1: 3 | Y1: 5 | Z1: 3 | AA1: 3 | AB1: 3 | AC1: 3 | AD1: 3 | AE1: 5
A2: 20 | B2: 2 | C2: 1 | D2: 12.5 | E2: 10 | F2: a | G2: Banana | H2: 200 | I2: 46337 | J2: +1 | K2: 1 | L2: 2 | M2: 3 | N2: 4 | P2: =SUM(A1) | S2: 25 | T2: 0.05 | U2: 25 | V2: 0.08 | W2: 0.05 | X2: 30 | Y2: 100 | Z2: 24 | AA2: 10 | AB2: 0 | AC2: 30 | AD2: 50 | AE2: 200
A3: TRUE | B3: 3 | C3: 50 | D3: 11 | E3: 50 | F3: e | G3: cherry | H3: 300 | J3: @SUM(A1) | P3: a* | S3: 50 | T3: 0.08 | U3: 50 | V3: 0.12 | W3: 0.1 | X3: 10 | Y3: 0 | Z3: 0 | AA3: 0 | AB3: 5 | AC3: 10 | AD3: 0 | AE3: 50
B4: 4 | C4: 100 | D4: 9.75 | E4: 20 | F4: b | G4: apple | H4: 400 | J4: -1 | P4: 0.00 | S4: 100 | T4: 0.12 | U4: 100 | V4: 0.16 | W4: 0.15 | X4: 0 | Y4: 0 | Z4: 0 | AA4: 0 | AB4: 0 | AC4: 0 | AD4: 0 | AE4: 0
A5: abc | B5: 5 | C5: 500 | D5: 8.4 | E5: 40 | F5: d | J5: x | S5: 250 | T5: 0.15 | U5: 250 | V5: 0.2 | W5: 0.2 | X5: 1000 | Y5: 1000 | Z5: 1000 | AA5: 1000 | AB5: 1000 | AC5: 1000 | AD5: 1000 | AE5: 1000
A6: 5 | J6: =HYPERLINK("x") | X6: 400 | Y6: 400 | Z6: 400 | AA6: 400 | AB6: 400 | AC6: 400 | AD6: 400 | AE6: 400
X7: 600 | Y7: 600 | Z7: 600 | AA7: 600 | AB7: 600 | AC7: 600 | AD7: 600 | AE7: 600
X8: 2 | Y8: 1 | Z8: 1 | AA8: 1 | AB8: 1 | AC8: 9 | AD8: 3 | AE8: 5
X9: entered | Y9: entered | Z9: entered | AA9: derived | AB9: entered | AC9: entered | AD9: entered | AE9: derived
X10: 200 | Y10: 0 | Z10: 0 | AA10: 0 | AB10: 0 | AC10: 200 | AD10: 0 | AE10: 0
X11: 2 | Y11: 0 | Z11: 0 | AA11: 1 | AB11: 0 | AC11: 2 | AD11: 0 | AE11: 3
X12: FALSE | Y12: FALSE | Z12: FALSE | AA12: TRUE | AB12: FALSE | AC12: FALSE | AD12: FALSE | AE12: TRUE
X13: FALSE | Y13: FALSE | Z13: FALSE | AA13: FALSE | AB13: FALSE | AC13: FALSE | AD13: FALSE | AE13: TRUE

Sheet About
A1: fancy-formula capture workbook v1. Every formula on Cases has NO cached value: Google Sheets computes them all.
A2: Upload to Google Drive, open as a Google Sheet, set File > Settings: Locale United States, Time zone (GMT+00:00) UTC.
A3: Let it recalculate, then File > Download > Microsoft Excel (.xlsx). Do not edit any cell.
A4: Record provenance.json beside the export (date, capturer, account type, locale, time zone, export route, sha256 of both files).
A5: scripts/build-formula-cases.py in fancy-conformance refuses an export it cannot trust.
